root - INFO - Bot started
telegram.ext.updater - WARNING - Exiting immediately!
2017-09-12 11:24:15,947 - INFO - Bot started
2017-09-12 11:31:14,546 - INFO - Bot started
2017-09-12 11:35:30,770 - INFO - Bot started
2017-09-12 11:35:34,796 - INFO - gj,gjg,
2017-09-12 13:35:34,905 - INFO - Bot started
2017-09-12 13:35:36,662 - INFO - ghbdtn
2017-09-12 13:35:39,167 - INFO - ghb
2017-09-12 14:11:29,895 - ERROR - Error while getting Updates: Timed out
2017-09-12 15:56:47,056 - ERROR - Error while getting Updates: Timed out
2017-09-12 15:56:49,182 - WARNING - Retrying (Retry(total=2, connect=None, read=None, redirect=None)) after connection broken by 'NewConnectionError('<telegram.vendor.ptb_urllib3.urllib3.connection.VerifiedHTTPSConnection object at 0x00000000035F9978>: Failed to establish a new connection: [Errno 11001] getaddrinfo failed',)': /bot427662093:AAG_rgSAM5cFkO7Li82-eCYcU1f10MUu8qw/getUpdates
2017-09-12 15:56:53,314 - WARNING - Retrying (Retry(total=1, connect=None, read=None, redirect=None)) after connection broken by 'NewConnectionError('<telegram.vendor.ptb_urllib3.urllib3.connection.VerifiedHTTPSConnection object at 0x00000000043B9A20>: Failed to establish a new connection: [Errno 11001] getaddrinfo failed',)': /bot427662093:AAG_rgSAM5cFkO7Li82-eCYcU1f10MUu8qw/getUpdates
2017-09-12 15:56:53,314 - WARNING - Retrying (Retry(total=0, connect=None, read=None, redirect=None)) after connection broken by 'NewConnectionError('<telegram.vendor.ptb_urllib3.urllib3.connection.VerifiedHTTPSConnection object at 0x00000000035F5B70>: Failed to establish a new connection: [Errno 11001] getaddrinfo failed',)': /bot427662093:AAG_rgSAM5cFkO7Li82-eCYcU1f10MUu8qw/getUpdates
2017-09-12 15:56:53,315 - ERROR - Error while getting Updates: urllib3 HTTPError HTTPSConnectionPool(host='api.telegram.org', port=443): Max retries exceeded with url: /bot427662093:AAG_rgSAM5cFkO7Li82-eCYcU1f10MUu8qw/getUpdates (Caused by NewConnectionError('<telegram.vendor.ptb_urllib3.urllib3.connection.VerifiedHTTPSConnection object at 0x00000000035F59E8>: Failed to establish a new connection: [Errno 11001] getaddrinfo failed',))
2017-09-12 15:56:54,817 - WARNING - Retrying (Retry(total=2, connect=None, read=None, redirect=None)) after connection broken by 'NewConnectionError('<telegram.vendor.ptb_urllib3.urllib3.connection.VerifiedHTTPSConnection object at 0x00000000035F5E10>: Failed to establish a new connection: [Errno 11001] getaddrinfo failed',)': /bot427662093:AAG_rgSAM5cFkO7Li82-eCYcU1f10MUu8qw/getUpdates
2017-09-12 15:56:54,818 - WARNING - Retrying (Retry(total=1, connect=None, read=None, redirect=None)) after connection broken by 'NewConnectionError('<telegram.vendor.ptb_urllib3.urllib3.connection.VerifiedHTTPSConnection object at 0x00000000035F5390>: Failed to establish a new connection: [Errno 11001] getaddrinfo failed',)': /bot427662093:AAG_rgSAM5cFkO7Li82-eCYcU1f10MUu8qw/getUpdates
2017-09-12 15:56:54,818 - WARNING - Retrying (Retry(total=0, connect=None, read=None, redirect=None)) after connection broken by 'NewConnectionError('<telegram.vendor.ptb_urllib3.urllib3.connection.VerifiedHTTPSConnection object at 0x00000000035F50F0>: Failed to establish a new connection: [Errno 11001] getaddrinfo failed',)': /bot427662093:AAG_rgSAM5cFkO7Li82-eCYcU1f10MUu8qw/getUpdates
2017-09-12 15:56:54,819 - ERROR - Error while getting Updates: urllib3 HTTPError HTTPSConnectionPool(host='api.telegram.org', port=443): Max retries exceeded with url: /bot427662093:AAG_rgSAM5cFkO7Li82-eCYcU1f10MUu8qw/getUpdates (Caused by NewConnectionError('<telegram.vendor.ptb_urllib3.urllib3.connection.VerifiedHTTPSConnection object at 0x00000000035F55C0>: Failed to establish a new connection: [Errno 11001] getaddrinfo failed',))
2017-09-12 15:56:57,070 - WARNING - Retrying (Retry(total=2, connect=None, read=None, redirect=None)) after connection broken by 'NewConnectionError('<telegram.vendor.ptb_urllib3.urllib3.connection.VerifiedHTTPSConnection object at 0x00000000035F5D68>: Failed to establish a new connection: [Errno 11001] getaddrinfo failed',)': /bot427662093:AAG_rgSAM5cFkO7Li82-eCYcU1f10MUu8qw/getUpdates
2017-09-12 15:56:57,071 - WARNING - Retrying (Retry(total=1, connect=None, read=None, redirect=None)) after connection broken by 'NewConnectionError('<telegram.vendor.ptb_urllib3.urllib3.connection.VerifiedHTTPSConnection object at 0x00000000035F56A0>: Failed to establish a new connection: [Errno 11001] getaddrinfo failed',)': /bot427662093:AAG_rgSAM5cFkO7Li82-eCYcU1f10MUu8qw/getUpdates
2017-09-12 15:56:57,071 - WARNING - Retrying (Retry(total=0, connect=None, read=None, redirect=None)) after connection broken by 'NewConnectionError('<telegram.vendor.ptb_urllib3.urllib3.connection.VerifiedHTTPSConnection object at 0x00000000035F5400>: Failed to establish a new connection: [Errno 11001] getaddrinfo failed',)': /bot427662093:AAG_rgSAM5cFkO7Li82-eCYcU1f10MUu8qw/getUpdates
2017-09-12 15:56:57,072 - ERROR - Error while getting Updates: urllib3 HTTPError HTTPSConnectionPool(host='api.telegram.org', port=443): Max retries exceeded with url: /bot427662093:AAG_rgSAM5cFkO7Li82-eCYcU1f10MUu8qw/getUpdates (Caused by NewConnectionError('<telegram.vendor.ptb_urllib3.urllib3.connection.VerifiedHTTPSConnection object at 0x00000000035F5668>: Failed to establish a new connection: [Errno 11001] getaddrinfo failed',))
2017-09-12 15:57:00,449 - WARNING - Retrying (Retry(total=2, connect=None, read=None, redirect=None)) after connection broken by 'NewConnectionError('<telegram.vendor.ptb_urllib3.urllib3.connection.VerifiedHTTPSConnection object at 0x00000000035F56D8>: Failed to establish a new connection: [Errno 11001] getaddrinfo failed',)': /bot427662093:AAG_rgSAM5cFkO7Li82-eCYcU1f10MUu8qw/getUpdates
2017-09-12 15:57:00,450 - WARNING - Retrying (Retry(total=1, connect=None, read=None, redirect=None)) after connection broken by 'NewConnectionError('<telegram.vendor.ptb_urllib3.urllib3.connection.VerifiedHTTPSConnection object at 0x00000000035F5F60>: Failed to establish a new connection: [Errno 11001] getaddrinfo failed',)': /bot427662093:AAG_rgSAM5cFkO7Li82-eCYcU1f10MUu8qw/getUpdates
2017-09-12 15:57:00,450 - WARNING - Retrying (Retry(total=0, connect=None, read=None, redirect=None)) after connection broken by 'NewConnectionError('<telegram.vendor.ptb_urllib3.urllib3.connection.VerifiedHTTPSConnection object at 0x00000000035F5240>: Failed to establish a new connection: [Errno 11001] getaddrinfo failed',)': /bot427662093:AAG_rgSAM5cFkO7Li82-eCYcU1f10MUu8qw/getUpdates
2017-09-12 15:57:00,451 - ERROR - Error while getting Updates: urllib3 HTTPError HTTPSConnectionPool(host='api.telegram.org', port=443): Max retries exceeded with url: /bot427662093:AAG_rgSAM5cFkO7Li82-eCYcU1f10MUu8qw/getUpdates (Caused by NewConnectionError('<telegram.vendor.ptb_urllib3.urllib3.connection.VerifiedHTTPSConnection object at 0x00000000035F58D0>: Failed to establish a new connection: [Errno 11001] getaddrinfo failed',))
2017-09-12 15:57:05,514 - WARNING - Retrying (Retry(total=2, connect=None, read=None, redirect=None)) after connection broken by 'NewConnectionError('<telegram.vendor.ptb_urllib3.urllib3.connection.VerifiedHTTPSConnection object at 0x00000000035F5278>: Failed to establish a new connection: [Errno 11001] getaddrinfo failed',)': /bot427662093:AAG_rgSAM5cFkO7Li82-eCYcU1f10MUu8qw/getUpdates
2017-09-12 15:57:05,515 - WARNING - Retrying (Retry(total=1, connect=None, read=None, redirect=None)) after connection broken by 'NewConnectionError('<telegram.vendor.ptb_urllib3.urllib3.connection.VerifiedHTTPSConnection object at 0x00000000035EA6D8>: Failed to establish a new connection: [Errno 11001] getaddrinfo failed',)': /bot427662093:AAG_rgSAM5cFkO7Li82-eCYcU1f10MUu8qw/getUpdates
2017-09-12 15:57:05,515 - WARNING - Retrying (Retry(total=0, connect=None, read=None, redirect=None)) after connection broken by 'NewConnectionError('<telegram.vendor.ptb_urllib3.urllib3.connection.VerifiedHTTPSConnection object at 0x00000000035EA390>: Failed to establish a new connection: [Errno 11001] getaddrinfo failed',)': /bot427662093:AAG_rgSAM5cFkO7Li82-eCYcU1f10MUu8qw/getUpdates
2017-09-12 15:57:05,516 - ERROR - Error while getting Updates: urllib3 HTTPError HTTPSConnectionPool(host='api.telegram.org', port=443): Max retries exceeded with url: /bot427662093:AAG_rgSAM5cFkO7Li82-eCYcU1f10MUu8qw/getUpdates (Caused by NewConnectionError('<telegram.vendor.ptb_urllib3.urllib3.connection.VerifiedHTTPSConnection object at 0x00000000035EA940>: Failed to establish a new connection: [Errno 11001] getaddrinfo failed',))
2017-09-12 15:57:13,110 - WARNING - Retrying (Retry(total=2, connect=None, read=None, redirect=None)) after connection broken by 'NewConnectionError('<telegram.vendor.ptb_urllib3.urllib3.connection.VerifiedHTTPSConnection object at 0x00000000035F5E48>: Failed to establish a new connection: [Errno 11001] getaddrinfo failed',)': /bot427662093:AAG_rgSAM5cFkO7Li82-eCYcU1f10MUu8qw/getUpdates
2017-09-12 15:57:13,111 - WARNING - Retrying (Retry(total=1, connect=None, read=None, redirect=None)) after connection broken by 'NewConnectionError('<telegram.vendor.ptb_urllib3.urllib3.connection.VerifiedHTTPSConnection object at 0x00000000035EAF60>: Failed to establish a new connection: [Errno 11001] getaddrinfo failed',)': /bot427662093:AAG_rgSAM5cFkO7Li82-eCYcU1f10MUu8qw/getUpdates
2017-09-12 15:57:13,111 - WARNING - Retrying (Retry(total=0, connect=None, read=None, redirect=None)) after connection broken by 'NewConnectionError('<telegram.vendor.ptb_urllib3.urllib3.connection.VerifiedHTTPSConnection object at 0x00000000035EA438>: Failed to establish a new connection: [Errno 11001] getaddrinfo failed',)': /bot427662093:AAG_rgSAM5cFkO7Li82-eCYcU1f10MUu8qw/getUpdates
2017-09-12 15:57:13,112 - ERROR - Error while getting Updates: urllib3 HTTPError HTTPSConnectionPool(host='api.telegram.org', port=443): Max retries exceeded with url: /bot427662093:AAG_rgSAM5cFkO7Li82-eCYcU1f10MUu8qw/getUpdates (Caused by NewConnectionError('<telegram.vendor.ptb_urllib3.urllib3.connection.VerifiedHTTPSConnection object at 0x00000000035EA470>: Failed to establish a new connection: [Errno 11001] getaddrinfo failed',))
2017-09-12 15:57:24,504 - WARNING - Retrying (Retry(total=2, connect=None, read=None, redirect=None)) after connection broken by 'NewConnectionError('<telegram.vendor.ptb_urllib3.urllib3.connection.VerifiedHTTPSConnection object at 0x00000000035F5F60>: Failed to establish a new connection: [Errno 11001] getaddrinfo failed',)': /bot427662093:AAG_rgSAM5cFkO7Li82-eCYcU1f10MUu8qw/getUpdates
2017-09-12 15:57:24,505 - WARNING - Retrying (Retry(total=1, connect=None, read=None, redirect=None)) after connection broken by 'NewConnectionError('<telegram.vendor.ptb_urllib3.urllib3.connection.VerifiedHTTPSConnection object at 0x00000000035F5C88>: Failed to establish a new connection: [Errno 11001] getaddrinfo failed',)': /bot427662093:AAG_rgSAM5cFkO7Li82-eCYcU1f10MUu8qw/getUpdates
2017-09-12 15:57:24,505 - WARNING - Retrying (Retry(total=0, connect=None, read=None, redirect=None)) after connection broken by 'NewConnectionError('<telegram.vendor.ptb_urllib3.urllib3.connection.VerifiedHTTPSConnection object at 0x00000000035F5F98>: Failed to establish a new connection: [Errno 11001] getaddrinfo failed',)': /bot427662093:AAG_rgSAM5cFkO7Li82-eCYcU1f10MUu8qw/getUpdates
2017-09-12 15:57:24,506 - ERROR - Error while getting Updates: urllib3 HTTPError HTTPSConnectionPool(host='api.telegram.org', port=443): Max retries exceeded with url: /bot427662093:AAG_rgSAM5cFkO7Li82-eCYcU1f10MUu8qw/getUpdates (Caused by NewConnectionError('<telegram.vendor.ptb_urllib3.urllib3.connection.VerifiedHTTPSConnection object at 0x00000000035F5400>: Failed to establish a new connection: [Errno 11001] getaddrinfo failed',))
2017-09-12 15:57:41,591 - WARNING - Retrying (Retry(total=2, connect=None, read=None, redirect=None)) after connection broken by 'NewConnectionError('<telegram.vendor.ptb_urllib3.urllib3.connection.VerifiedHTTPSConnection object at 0x00000000035F5240>: Failed to establish a new connection: [Errno 11001] getaddrinfo failed',)': /bot427662093:AAG_rgSAM5cFkO7Li82-eCYcU1f10MUu8qw/getUpdates
2017-09-12 15:57:41,592 - WARNING - Retrying (Retry(total=1, connect=None, read=None, redirect=None)) after connection broken by 'NewConnectionError('<telegram.vendor.ptb_urllib3.urllib3.connection.VerifiedHTTPSConnection object at 0x00000000035F5EF0>: Failed to establish a new connection: [Errno 11001] getaddrinfo failed',)': /bot427662093:AAG_rgSAM5cFkO7Li82-eCYcU1f10MUu8qw/getUpdates
2017-09-12 15:57:41,592 - WARNING - Retrying (Retry(total=0, connect=None, read=None, redirect=None)) after connection broken by 'NewConnectionError('<telegram.vendor.ptb_urllib3.urllib3.connection.VerifiedHTTPSConnection object at 0x00000000035F5128>: Failed to establish a new connection: [Errno 11001] getaddrinfo failed',)': /bot427662093:AAG_rgSAM5cFkO7Li82-eCYcU1f10MUu8qw/getUpdates
2017-09-12 15:57:41,593 - ERROR - Error while getting Updates: urllib3 HTTPError HTTPSConnectionPool(host='api.telegram.org', port=443): Max retries exceeded with url: /bot427662093:AAG_rgSAM5cFkO7Li82-eCYcU1f10MUu8qw/getUpdates (Caused by NewConnectionError('<telegram.vendor.ptb_urllib3.urllib3.connection.VerifiedHTTPSConnection object at 0x00000000035F5390>: Failed to establish a new connection: [Errno 11001] getaddrinfo failed',))
2017-09-14 11:28:11,958 - ERROR - Error while getting Updates: Timed out
2017-09-14 11:46:59,655 - INFO - ghbdtn
2017-09-14 12:16:42,944 - ERROR - Error while getting Updates: Timed out
2017-09-14 13:32:57,971 - ERROR - Error while getting Updates: Timed out
2017-09-14 14:13:00,571 - ERROR - Error while getting Updates: Timed out
2017-09-15 09:18:14,507 - ERROR - Error while getting Updates: Timed out
2017-09-15 10:09:44,610 - ERROR - Error while getting Updates: Timed out
2017-09-15 10:18:55,370 - INFO - Bot started
2017-09-15 10:18:56,501 - INFO - jdhfjds
2017-09-15 10:19:08,268 - ERROR - Error while getting Updates: Timed out
